Workbook

Sheet Enero 2025
A2: CODIGO DEL GRUPO | B2: NOMBRE DEL GRUPO | C2: HOTELES | D2: FECHA DE ESTANCIA | E2: CONFIRMACION | F2: TARIFAS QUE APLICAN | G2: Sale Price PAXIMUM | H2: TOUCH COST | I2: PROFIT %
A3: 78950745 | B3: FIT - PAXIMUN | C3: Grand Aston Habana | D3: 06.01 - 09.01 | E3: RL:21113 | F3: File mutlu - reserva de paximun sistema online | G3: 672 | H3: 540 | I3: =G3/H3 -> 1.2444444
A4: 78950916 | B4: Paximun | C4: Memories miramar | D4: 21.01 - 23.01 | E4: No:308495 | F4: CXX
G5: =SUM(G3:G4) -> 672 | H5: =SUM(H3:H4) -> 540

Sheet Febrero 2025
B2: CODIGO DEL GRUPO | C2: NOMBRE DEL GRUPO | D2: HOTELES | E2: FECHA DE ESTANCIA | F2: CONFIRMACION | G2: TARIFAS QUE APLICAN | H2: Sale Price PAXIMUM | I2: TOUCH COST | J2: PROFIT %
A3: OK | B3: 78951111 | C3: Paximun | D3: MEMORIES MIRAMAR | E3: 09.02 - 11.02 | F3: No:308910 | H3: 188 | I3: 172 | J3: =H3/I3 -> 1.0930233
A4: OK | B4: 78951122 | C4: Paximun | D4: Memories Trinidad | E4: 07.02 - 09.02 | F4: 117673 | H4: 210 | I4: 162 | J4: =H4/I4 -> 1.2962963
A5: ok | B5: 78951191 | C5: Paximun | D5: MEMORIES MIRAMAR | E5: 09.02 - 11.02 | F5: No:309052 | H5: 188 | I5: 172 | J5: =H5/I5 -> 1.0930233
A6: ok | B6: 78951154 | C6: Paximun | D6: Gran Aston Cayo Las Brujas | E6: 13.02 - 15.02 | F6: 48253 | H6: 176 | I6: 136 | J6: =H6/I6 -> 1.2941176
A7: ok | B7: 78951298 | C7: Paximun | D7: Selectum Varadero | E7: 14.02 - 16.02 | F7: RL-17209 | G7: 2 pax | H7: 252 | I7: 200 | J7: =H7/I7 -> 1.26
A8: ok | B8: 78951228 | C8: Paximun | D8: Grand Aston Varadero | E8: 14.02 - 21.02 | F8: Rl-20320 | G8: 2 pax | H8: 770 | I8: 700 | J8: =H8/I8 -> 1.1
A9: ok | B9: 78951301 | C9: Paximun | D9: Grand Aston Habana | E9: 15.02 - 16.02 | F9: RL:11738 | G9: 2 pax | H9: 142 | I9: 90 | J9: =H9/I9 -> 1.5777778
A10: ok | B10: 78951180 | C10: Paximun | D10: MEMORIES MIRAMAR | E10: 16.02 - 17.02 | F10: No:309011 | G10: cxxx | J10: =H10/I10 -> #DIV/0!
B11: 78951454 | C11: Paximun | D11: Ib. Parque Central | E11: 27.02 - 02.03 | F11: R/1672415 | G11: CXXX | J11: =H11/I11 -> #DIV/0!
B12: 78951485 | C12: Paximun | D12: Ib. Parque Central | E12: 27.02 - 02.03 | F12: R/1672449 | G12: CXXX | J12: =H12/I12 -> #DIV/0!
A13: OK | B13: 78951109 | C13: Paximun | D13: Aston Habana | E13: 09.02 - 16.02 | F13: RL:21967 | G13: cxx | J13: =H13/I13 -> #DIV/0!
H14: =SUM(H3:H13) -> 1926 | I14: =SUM(I3:I13) -> 1632

Sheet MARZO 2025
A2: CODIGO DEL GRUPO | B2: NOMBRE DEL GRUPO | C2: HOTELES | D2: FECHA DE ESTANCIA | E2: CONFIRMACION | F2: TARIFAS QUE APLICAN /Observaciones | G2: Sale Price PAXIMUM | H2: TOUCH COST | I2: PROFIT %
A3: 78951488 | B3: Paximun | C3: Grand Aston Habana | D3: 02.03 - 03.03 | E3: RL:22815 - se solicitaron como grupo | F3: 1 pax, cxxx
A4: 78951489 | B4: Paximun | C4: Grand Aston Habana | D4: 02.03 - 03.03 | F4: 1 pax
A5: 78951490 | B5: Paximun | C5: Grand Aston Habana | D5: 02.03 - 03.03 | F5: 2 pax
A6: 78951491 | B6: Paximun | C6: Grand Aston Habana | D6: 02.03 - 03.03 | F6: 1 pax | G6: 76 | H6: 55 | I6: =G6/H6 -> 1.3818182
A7: 78951492 | B7: Paximun | C7: Grand Aston Habana | D7: 02.03 - 03.03 | F7: 1 pax | G7: 76 | H7: 55 | I7: =G7/H7 -> 1.3818182
A8: 78951550 | B8: Paximun | C8: MYSTIQUE LA POPA | D8: 02.03 - 03.03 | E8: RL 6009 | F8: 2 pax | G8: 292 | H8: 280 | I8: =G8/H8 -> 1.0428571
A9: 78951460 | B9: Paximun | C9: MYSTIQUE LA POPA | D9: 03.03 - 05.03 | E9: RL 5969, | G9: 282 | H9: 272 | I9: =G9/H9 -> 1.0367647
A10: 78951497 | B10: Paximun | C10: Grand aston habana | D10: 04.03 - 05.03 | E10: Ok.145951 | F10: 2 pax | G10: 114 | H10: 110 | I10: =G10/H10 -> 1.0363636
A11: 78951689 | B11: Paximun | C11: Grand Aston Habana | D11: 21.03 - 22.03 | E11: RL 23188. | G11: 114 | H11: 100 | I11: =G11/H11 -> 1.14
A12: 78951337 | B12: Paximun | C12: MYSTIQUE LA POPA | D12: 28.03 - 01.04 | E12: RL 5901 | G12: 584 | H12: 560 | I12: =G12/H12 -> 1.0428571
A13: 78951715 | B13: Paximun | C13: Grand Aston Varadero | D13: 29.03 - 30.03 | E13: RL-21939 | F13: 2 pax (CANCELADO 14.03.25) | I13: =G13/H13 -> #DIV/0!
A14: 78951878 | B14: Paximun | C14: Grand Aston Varadero | D14: 29.03 - 30.03 | E14: RL-22659 | F14: 2 pax reserva idem a la 78951715 | G14: 110 | H14: 100 | I14: =G14/H14 -> 1.1
A15: 78951631 | B15: Paximun | C15: Grand Memories Varadero | D15: 30.03 - 04.04 | E15: RL/361682 | F15: 2 pax | G15: 478 | H15: 444 | I15: =G15/H15 -> 1.0765766
G16: =SUM(G6:G15) -> 2126 | H16: =SUM(H6:H15) -> 1976

Sheet ABRIL 2025
B2: CODIGO PAXIMUM | C2: NOMBRE DEL CLIENTE | D2: HOTELES | E2: DESDE | F2: HASTA | G2: CONFIRMACION | H2: PAX / HAB | I2: VENTA PAXIMUM | J2: COSTO HOTEL | K2: PROFIT % | L2: TARIFAS QUE APLICAN | M2: REMARKS
A3: x | B3: 78952083 | C3: Paximum | D3: Memories Miramar | E3: 45748 | F3: 45752 | G3: No: 310538. | H3: 2 pax | I3: 288 | J3: 264 | K3: =I3/J3 -> 1.0909091
A4: x | B4: 78952037 | C4: Paximun | D4: Mystique Trinidad La Popa | E4: 45748 | F4: 45749 | G4: RL 6225 | H4: 2 pax | I4: 118 | J4: 114 | K4: =I4/J4 -> 1.0350877 | L4: 2025 TUR 001
A5: x | B5: 78952136 | C5: Paximum | D5: Gran Aston Varadero | E5: 45750 | F5: 45751 | G5: RL-23398 | H5: 2pax | I5: 98 | J5: 80 | K5: =I5/J5 -> 1.225 | L5: SUPER EBB 2025 - 002
B6: 78952055 | C6: Paximun | D6: Gran Memories Varadero | E6: 45751 | F6: 45755 | G6: RL/ 362916 (CXX) | H6: 4 pax / 2 HAB | K6: =I6/J6 -> #DIV/0! | L6: 2025 TUR 001
B7: 78951086 | C7: Paximun | D7: Grand Aston Varadero | E7: 45752 | F7: 45753 | G7: RL 19667 (CXX) | K7: =I7/J7 -> #DIV/0!
A8: x | B8: 78951809 | C8: Paximun | D8: Gran Aston Varadero | E8: 45752 | F8: 45753 | G8: RL-22539 | H8: 2 pax | I8: 118 | J8: 100 | K8: =I8/J8 -> 1.18 | L8: PROMO - SUPER EBB 2025 - 002 | M8: idem a la 78951086
A9: x | B9: 78952041 | C9: Paximun | D9: Memories Miramar | E9: 45754 | F9: 45760 | G9: No. 310447. | H9: 1 pax | I9: 414 | J9: 348 | K9: =I9/J9 -> 1.1896552 | L9: 2025 TUR 001
A10: x | B10: 78952078 | C10: Paximun | D10: Selectum Family Varadero | E10: 45758 | F10: 45760 | G10: RL-19226 | H10: 2 pax | I10: 216 | J10: 192 | K10: =I10/J10 -> 1.125 | L10: Oferta Summer Promotion 2025 | M10: problemas correo de B2B llego por correo de extranet
A11: x | B11: 78951441 | C11: Paximun | D11: Grand Memories Varadero | E11: 45761 | F11: 45765 | G11: RL/360970 | H11: 4 pax | I11: 656 | J11: 608 | K11: =I11/J11 -> 1.0789474
B12: 78951839 | C12: Paximun | D12: Mystique Trinidad La Popa | E12: 45761 | F12: 45766 | G12: RL 6144 (CXX) | H12: 1 pax | K12: =I12/J12 -> #DIV/0! | L12: 2025 TUR 001
A13: x | B13: 78952265 | C13: Paximun | D13: Selectum Family Varadero | E13: 45765 | F13: 45767 | G13: RL-19523 | H13: 2 PAX | I13: 216 | J13: 168 | K13: =I13/J13 -> 1.2857143 | L13: B2B Special Promotion
A14: x | B14: 78951718 | C14: Paximun | D14: Grand Aston Habana | E14: 45767 | F14: 45768 | G14: 23271 | H14: 2 pax | I14: 114 | J14: 98 | K14: =I14/J14 -> 1.1632653 | L14: PROMO - SUPER EBB 2025 - 002
B15: 78951756 | C15: Paximun | D15: Memories Miramar | E15: 45770 | F15: 45771 | G15: No:310050 (CXX) | H15: 2 pax | K15: =I15/J15 -> #DIV/0! | L15: 2025 TUR 001
B16: 78951761 | C16: Paximun | D16: Memories Miramar | E16: 45770 | F16: 45771 | G16: No:310044 (CXX) | H16: 6 pax / 3 DBL | K16: =I16/J16 -> #DIV/0! | L16: 2025 TUR 001
A17: x | B17: 78952558 | C17: Paximun | D17: Memories Miramar | E17: 45771 | F17: 45772 | G17: No. 311037 | H17: 2 pax | I17: 72 | J17: 66 | K17: =I17/J17 -> 1.0909091 | L17: 2025 TUR 003
I19: =SUM(I3:I17) -> 2310 | J19: =SUM(J3:J18) -> 2038 | K19: =I19/J19 -> 1.1334642
I21: Revenue | J21: =I19-J19 -> 272

Sheet MAYO 2025
B2: PAXIMUM CODE | C2: CLIENTS NAMES | D2: HOTELS | E2: From | F2: to | G2: Hotel confirmation | H2: PAX / ROOM | I2: Sale Price PAXIMUM | J2: TOUCH COST | K2: PROFIT % | L2: VALID RATES TO APPLY | M2: REMARKS
A3: x | B3: 78952482 | C3: Paximum | D3: Grand Aston Habana | E3: 45779 | F3: 45780 | G3: RL:24364 | H3: 1 pax | I3: 91 | J3: 74 | K3: =I3/J3 -> 1.2297297 | L3: PROMO - SUPER EBB 2025 - 002
A4: x | B4: 78952045 | C4: Paximum | D4: Grand Aston Habana | E4: 45779 | F4: 45780 | G4: RL:23811 | H4: 2 pax / 1 HAB | I4: 114 | J4: 98 | K4: =I4/J4 -> 1.1632653 | L4: PROMO - SUPER EBB 2025 - 002
B5: 78952301 | C5: Paximum | D5: Mystique Trinidad La Popa | E5: 45780 | F5: 45781 | G5: RL 6292 (CXX) | H5: 2 pax / 1 HAB | I5: 0 | J5: 0 | K5: =I5/J5 -> #DIV/0! | L5: 2025 TUR 003
A6: x | B6: 78952481 | C6: Paximum | D6: Grand Aston Habana | E6: 45785 | F6: 45786 | G6: RL:24362 | H6: 1 PAX | I6: 91 | J6: 74 | K6: =I6/J6 -> 1.2297297 | L6: PROMO - SUPER EBB 2025 - 002
A7: x | B7: 78951999 | C7: Mrs MARIA JOSE DANGOND DAVID /Mr DANNY FERNANDO RAMIREZ BASTIDAS | D7: Memories Miramar | E7: 45792 | F7: 45795 | G7: No. 310385. | H7: 2 pax / 1 HAB | I7: 204 | J7: 192 | K7: =I7/J7 -> 1.0625 | L7: 2025 TUR 001
A8: x | B8: 78952949 | C8: Roberto Estevez Torres | D8: Selectum Family Varadero | E8: 45800 | F8: 45803 | G8: RL-20480 | H8: 2 pax / 1 HAB | I8: 324 | J8: 252 | K8: =I8/J8 -> 1.2857143 | L8: B2B Special Promotion
A9: x | B9: 78953170 | C9: MAIBEL SANCHEZ / MANUEL SIMON | D9: Selectum Family Varadero | E9: 45807 | F9: 45809 | G9: RL-20749 | H9: 4 pax / 2 DBL | I9: 432 | J9: 336 | K9: =I9/J9 -> 1.2857143 | L9: B2B Special Promotion
I12: =SUM(I3:I11) -> 1256 | J12: =SUM(J3:J11) -> 1026 | K12: =I12/J12 -> 1.2241715
I14: Revenue | J14: =I12-J12 -> 230

Sheet JUNIO 2025
B2: PAXIMUM CODE | C2: CLIENTS NAMES | D2: HOTELS | E2: From | F2: to | G2: Hotel confirmation | H2: PAX / ROOM | I2: Sale Price PAXIMUM | J2: TOUCH COST | K2: PROFIT % | L2: VALID RATES TO APPLY | M2: REMARKS
A3: x | B3: 78953064 | C3: Pavlov x 3 | D3: Sol Caribe Beach | E3: 45821 | F3: 45823 | G3: No. 29237 | H3: 3 pax / 1 hab | I3: 364 | J3: 307.98 | K3: =I3/J3 -> 1.1818949 | L3: 2025ITA1438
A4: x | B4: 78953501 | C4: Mr KIIAMOV MARAT | D4: Melia Internacional | E4: 45821 | F4: 45822 | G4: 197514 | H4: 1 pax / 1 sgl | I4: 184 | J4: 157.5 | K4: =I4/J4 -> 1.168254 | L4: 2025ITA2546
A5: x | B5: 78952917 | C5: Ruben Ramirez x2 | D5: Mystique Trinidad La Popa | E5: 45824 | F5: 45826 | G5: RL 6501 | H5: 2 pax / 1 hab | I5: 168 | J5: 160 | K5: =I5/J5 -> 1.05 | L5: 2025 TUR 001
A6: x | B6: 78952913 | C6: Francisco Sanchez x2 | D6: Mystique Trinidad La Popa | E6: 45824 | F6: 45826 | G6: RL 6502 | H6: 2 pax / 1 hab | I6: 168 | J6: 160 | K6: =I6/J6 -> 1.05 | L6: 2025 TUR 001
A7: x | B7: 78952920 | C7: Juan Lorenzo x2 | D7: Mystique Trinidad La Popa | E7: 45824 | F7: 45826 | G7: RL 6503 | H7: 3 pax / 1 hab | I7: 168 | J7: 160 | K7: =I7/J7 -> 1.05 | L7: 2025 TUR 001
B8: 78951634 | C8: Paximun | D8: Selectum Varadero | E8: 45824 | F8: 45825 | G8: RL-18239 (CXX) | I8: 0 | J8: 0 | K8: =I8/J8 -> #DIV/0!
A9: x | B9: 78953748 | C9: ANDREA ETIHEL x2 | D9: Melia Cayo Santa Maria | E9: 45468 | F9: 45379 | G9: 163286 | H9: 2 PAX / 1 DBL | I9: 252 | J9: 239.4 | K9: =I9/J9 -> 1.0526316 | L9: 2025ITA2546 | M9: markup 5%
A10: x | B10: 78953618 | C10: ISLAM BAKHMUDOV | D10: Melia Internacional | E10: 27/6/20025 | F10: 45836 | G10: 198580 | H10: 2 PAX / 1 DBL | I10: 182 | J10: 154 | K10: =I10/J10 -> 1.1818182 | L10: 2025ITA2546
A11: x | B11: 78953711 | C11: Isabel Varela x 2 | D11: Melia Las Dunas | E11: 45835 | F11: 45837 | G11: 358862 | H11: 2 PAX / 1 DBL | I11: 184 | J11: 145.6 | K11: =I11/J11 -> 1.2637363 | L11: 2025ITA2546
A12: x | B12: 78953800 | C12: Pawel Duraczynski x2 | D12: Melia Varadero | E12: 45835 | F12: 45837 | G12: No .639005 | H12: 2 PAX / 1 DBL | I12: 232 | J12: 221 | K12: =I12/J12 -> 1.0497738 | L12: 2025ITA2546 | M12: markup 5%
A13: x | B13: 78953911 | C13: GIANANNIBALE MIGLIOLI | D13: Melia Internacional | E13: 45836 | F13: 45838 | G13: numero 201012 | H13: 2 PAX / 1 DBL | I13: 324 | J13: 308 | K13: =I13/J13 -> 1.0519481 | L13: 2025ITA2547 | M13: markup 5%
A14: x | B14: 78953855 | C14: Wendy Besada x2 | D14: Melia Peninsula Varadero | E14: 45837 | F14: 45840 | G14: No .377720 | H14: 2 PAX / 1 DBL | I14: 246 | J14: 234 | K14: =I14/J14 -> 1.0512821 | L14: 2025ITA2923 | M14: Markup 5%/ New SPO
I22: =SUM(I3:I21) -> 2472 | J22: =SUM(J3:J21) -> 2247.48 | K22: =I22/J22 -> 1.0998986
I24: Revenue | J24: =I22-J22 -> 224.52

Sheet JULIO 2025
B2: PAXIMUM CODE | C2: CLIENTS NAMES | D2: HOTELS | E2: From | F2: to | G2: Hotel confirmation | H2: PAX / ROOM | I2: Sale Price PAXIMUM | J2: TOUCH COST | K2: PROFIT % | L2: VALID RATES TO APPLY | M2: REMARKS
A3: x | B3: 78953873 | C3: MARIO MARTINEZ /RUBEN ANTON BELTRAN /KATIUSKA DIAZ GUIBERT | D3: Paradisus Varadero | E3: 45839 | F3: 45843 | G3: No.358562 | H3: 8 pax / 2 TRP+ 1 DBL | I3: 1632.4 | J3: 1644 | K3: =I3/J3 -> 0.99294404 | L3: 2025ITA2546 | M3: incidencia / cambio a 1 triple + 2 dobles
B4: 78953879 | C4: NESTOR LEONARDO / NICOLAS GOMEZ | D4: Paradisus Varadero | E4: 45840 | F4: 45844 | G4: CXX | H4: 4 pax / 2 DBL | I4: 0 | J4: 0 | K4: =I4/J4 -> #DIV/0! | L4: 2025ITA2546 | M4: markup 5%
A5: x | B5: 78953885 | C5: NESTOR LEONARDO / NICOLAS GOMEZ | D5: Paradisus Varadero | E5: 45842 | F5: 45846 | G5: No.358577 | H5: 4+1 pax / 2 DBL | I5: 848 | J5: 960 | K5: =I5/J5 -> 0.88333333 | L5: 2025ITA2546 | M5: incidencia
A6: x | B6: 78953922 | C6: RAZVAN VASILE | D6: Paradisus Varadero | E6: 45842 | F6: 45848 | G6: No.358581 | H6: 3 pax / 1 TRP | I6: 1077.3 | J6: 444.6 | K6: =I6/J6 -> 2.4230769 | L6: 2025ITA2546 | M6: JS Sea View incidencia / salida imprevista
B7: 78953847 | C7: Olivia Ezaru | D7: Paradisus Varadero | E7: 45842 | F7: 45848 | G7: CXX | H7: 3 pax / 1 TRP | I7: 0 | J7: 0 | K7: =I7/J7 -> #DIV/0! | L7: 2025ITA2546 | M7: markup 5%
A8: x | B8: 78953877 | C8: JOSE CASTANEDA /LAURA CASTANEDA | D8: Paradisus Varadero | E8: 45845 | F8: 45849 | G8: No.358576 | H8: 4 pax / 2 DBL | I8: 848 | J8: 960 | K8: =I8/J8 -> 0.88333333 | L8: 2025ITA2546 | M8: incidencia
B9: 78953762 | C9: TOMAS ISAAC NOWICKI /LUDMILA AYELEN | D9: MELIA INTERNATIONAL | E9: 45846 | F9: 45853 | G9: 199938 (CXX) | H9: 2 PAX / 1 HAB | I9: 0 | J9: 0 | K9: =I9/J9 -> #DIV/0! | L9: 2025ITA2546 | M9: markup 5%
B10: 78953757 | C10: NATASHA REBECA NOWICKI/MARTIN GABRIEL CASCABELO | D10: MELIA INTERNATIONAL | E10: 45846 | F10: 45853 | G10: CXX | H10: 2 PAX / 1 HAB | I10: 0 | J10: 0 | K10: =I10/J10 -> #DIV/0! | L10: 2025ITA2546 | M10: markup 5%
A11: x | B11: 78953889 | C11: Roberto Morales X2 | D11: MELIA LAS DUNAS | E11: 45849 | F11: 45850 | G11: número 359399 | H11: 2 PAX / 1 DBL | I11: 76 | J11: 72.8 | K11: =I11/J11 -> 1.043956 | L11: 2025ITA2546 | M11: markup 5%
A12: x | B12: 78954172 | C12: Heather Jennings x2 | D12: Sol Palmeras | E12: 45849 | F12: 45851 | G12: ok | H12: 2 PAX / 1 DBL | I12: 288 | J12: 286 | K12: =I12/J12 -> 1.006993 | L12: 2015ITA2923 | M12: confirma Bungalow por SS
B13: 78953768 | C13: vALENTINA pistarini /franco nahuel | D13: MELIA VARADERO | E13: 45850 | F13: 45857 | G13: CXX | H13: 2 PAX / 1 HAB | I13: 0 | J13: 0 | K13: =I13/J13 -> #DIV/0! | L13: 2025ITA2546 | M13: markup 5%
A14: x | B14: 78953215 | C14: RODRIGO ADRIAN /MAURICIO GABRIEL | D14: MEMORIES TRINIDAD DEL MAR | E14: 45852 | F14: 45853 | G14: 119718 | H14: 4 pax / 2 DBL | I14: 166 | J14: 164 | K14: =I14/J14 -> 1.0121951 | L14: 2025 TUR 003 TOUCH
A15: x | B15: 78953858 | C15: FELIX ARTURO BESANO x2 | D15: Melia Internacional | E15: 45852 | F15: 45859 | G15: 200627 | H15: 2 pax / 1 HAB | I15: 1134 | J15: 1078 | K15: =I15/J15 -> 1.0519481 | L15: 2025ITA2546 | M15: markup 5%
A16: x | B16: 78954267 | C16: Dogukan GEDIK | D16: Melia Cohiba | E16: 45852 | F16: 45854 | G16: 710451 | H16: 1 pax / 1 HAB (SV) | I16: 202 | J16: 144 | K16: =I16/J16 -> 1.4027778 | L16: 2025ITA2546 | M16: markup 5% / reserva original Melia Habana, desvío con upgrade a the level
A17: x | B17: 78954267 | C17: Ayse A Ozcan | D17: Melia Cohiba | E17: 45852 | F17: 45854 | G17: 710451 | H17: 1 pax / 1 HAB | I17: 166 | J17: 144 | K17: =I17/J17 -> 1.1527778 | L17: 2025ITA2546 | M17: markup 5% / reserva original Melia Habana, desvío con upgrade a the level
A18: x | B18: 78953733 | C18: ERNESTO BALERIO x 2 | D18: MELIA INTERNATIONAL | E18: 45852 | F18: 45860 | G18: 199697 | H18: 2 PAX / 1 HAB | I18: 1296 | J18: 1232 | K18: =I18/J18 -> 1.0519481 | L18: 2025ITA2164 | M18: markup 5%
B19: 78952546 | C19: Marco Colnago / Pietro Redaelli | D19: Mystique Trinidad La Popa | E19: 45853 | F19: 45855 | G19: RL 6389 (CXX) | H19: 2 PAX / 1 HAB | I19: 0 | J19: 0 | K19: =I19/J19 -> #DIV/0! | L19: 2025 TUR 003 TOUCH | M19: No CXX, cambiar LOC
A20: x | B20: 78954024 | C20: Marco Colnago / Pietro Redaelli | D20: Mystique Trinidad La Popa | E20: 45853 | F20: 45855 | G20: RL 6389 | H20: 2 PAX / 1 HAB | I20: 162 | J20: 152 | K20: =I20/J20 -> 1.0657895 | L20: 2026 TUR 003 TOUCH
A21: x | B21: 78954221 | C21: Francesc Garcia | D21: Melia Cohiba | E21: 45854 | F21: 45858 | G21: 710452 | H21: 1 pax / 1 HAB | I21: 332 | J21: 288 | K21: =I21/J21 -> 1.1527778 | L21: 2025ITA2546 | M21: markup 5% / reserva original Melia Habana, desvío con upgrade a the level
A22: x | B22: 78954387 | C22: Madeleine Ihle /Bjorn Seidler | D22: Paradisus Princesa del Mar | E22: 45854 | F22: 17/7/20253 | G22: No .258119 | H22: 2 PAX / 1 HAB | I22: 136 | J22: 130 | K22: =I22/J22 -> 1.0461538 | L22: 2025ITA2546 | M22: markup 5%
B23: 78953860 | C23: RICARDO ANTONIO /ARIEL GOMEZ PALACIOS / SERGIO ALEJANDRO | D23: MELIA LAS DUNAS | E23: 45854 | F23: 45862 | G23: No 359295 (CXX) | H23: 6+1 pax / 3 DBL | I23: 0 | J23: 0 | K23: =I23/J23 -> #DIV/0! | L23: 2025ITA2546 | M23: markup 5%
A24: x | B24: 78953869 | C24: Mileidy Gonzalez /Roday Rosendo | D24: MELIA LAS DUNAS | E24: 45856 | F24: 45858 | G24: No 359296 . | H24: 4 pax / 2 DBL | I24: 304 | J24: 291.2 | K24: =I24/J24 -> 1.043956 | L24: 2025ITA2546 | M24: markup 5%
B25: 78953857 | C25: DAVID NAHUEL CANAS | D25: Melia Internacional | E25: 45856 | F25: 45863 | G25: 200558 CXX | H25: 2+2 / 1 HAB | I25: 0 | J25: 0 | K25: =I25/J25 -> #DIV/0! | L25: 2025ITA2164 | M25: markup 5%
B26: 78954157 | C26: HERNAN BECK x2 | D26: Sol Palmeras | E26: 45859 | F26: 45867 | G26: CXX | H26: 2 PAX / 1 HAB | I26: 0 | J26: 0 | K26: =I26/J26 -> #DIV/0! | L26: 2015ITA2923 | M26: Markup 5%
B27: 78953347 | C27: Daniel Enrique Lozano x2 | D27: MELIA LAS DUNAS | E27: 45861 | F27: 45862 | G27: 357719 (CXX) | H27: 2 PAX / 1 HAB | I27: 0 | J27: 0 | K27: =I27/J27 -> #DIV/0! | L27: 2025ITA2164
B28: 78953740 | C28: Daniel Enrique Lozano x2 | D28: MELIA LAS DUNAS | E28: 45861 | F28: 45862 | G28: No 358943 (CXX) | H28: 2 PAX / 1 HAB | I28: 0 | J28: 0 | K28: =I28/J28 -> #DIV/0! | L28: 2025ITA2164 | M28: rebooking
A29: x | B29: 78953771 | C29: Daniel Enrique Lozano x2 | D29: MELIA LAS DUNAS | E29: 45861 | F29: 45862 | G29: No 359211 | H29: 2 PAX / 1 HAB | I29: 76 | J29: 72.8 | K29: =I29/J29 -> 1.043956 | L29: 2025ITA2164 | M29: rebooking
B30: 78953817 | C30: Olga Lidia Cruz x3 | D30: Melia Varadero | E30: 45862 | F30: 45896 | G30: BK-639149 (CXX) | H30: 2+1 / 1 DBL | I30: 0 | J30: 0 | K30: =I30/J30 -> #DIV/0! | L30: 2025ITA2164 | M30: markup 5%
B31: 78953818 | C31: Adalis Suarez x2 | D31: Melia Varadero | E31: 45862 | F31: 45896 | G31: No .639151(CXX) | H31: 4 pax / 2 DBL | I31: 0 | J31: 0 | K31: =I31/J31 -> #DIV/0! | L31: 2025ITA2164 | M31: markup 5%
B32: 78953819 | C32: Arlety Quintana x2 | D32: Melia Varadero | E32: 45862 | F32: 45896 | G32: No .639166 (CXX) | H32: 2 pax / 1 DBL | I32: 0 | J32: 0 | K32: =I32/J32 -> #DIV/0! | L32: 2025ITA2164 | M32: Compraron Premium sin rebaja de oferta/ se confirma upgrade a The Level, se puede subir mas a Level sea view si exigen vista
A33: x | B33: 78953990 | C33: EKATERINA KVASHNINA x 2 | D33: Melia Peninsula | E33: 45867 | F33: 45871 | G33: No 378159 | H33: 2 pax / 1 DBL | I33: 328 | J33: 312 | K33: =I33/J33 -> 1.0512821 | L33: 2015ITA2923 | M33: markup 5%
A34: x | B34: 78953321 | C34: Philip Gard | D34: MYSTIQUE TRINIDAD BY ROYALTON | E34: 45869 | F34: 45873 | G34: RL 6596 | H34: 1 pax / 1 HAB | I34: 244 | J34: 232 | K34: =I34/J34 -> 1.0517241 | L34: 2025 TUR 003 TOUCH
B35: 78954135 | C35: MELINA DEL VALLE x2 | D35: Melia Las Antillas | E35: 45869 | F35: 45877 | G35: CXX | H35: 2 pax / 1 DBL | I35: 0 | J35: 0 | K35: =I35/J35 -> #DIV/0! | L35: 2025ITA2164 | M35: markup 5%
I40: =SUM(I3:I39) -> 9315.7 | J40: =SUM(J3:J39) -> 8607.4 | K40: =I40/J40 -> 1.0822897
I42: Revenue | J42: =I40-J40 -> 708.3

Sheet AGOSTO 2025
B2: PAXIMUM CODE | C2: CLIENTS NAMES | D2: HOTELS | E2: From | F2: to | G2: Hotel confirmation | H2: PAX / ROOM | I2: Sale Price PAXIMUM | J2: TOUCH COST | K2: PROFIT % | L2: VALID RATES TO APPLY | M2: REMARKS
A3: x | B3: 78954833 | C3: Cordula Stadter | D3: Melia Trinidad Peninsula | E3: 45872 | F3: 45875 | G3: No. 24413 | H3: 2 pax / 1 DBL | I3: 384 | J3: 365.4 | K3: =I3/J3 -> 1.0509031 | L3: 2025ITA2546 | M3: Markup 5%
B4: 78954065 | C4: MARIA GABRIELA SILVA /PAUL NICOLAS PAREDES | D4: Melia Internacional Varadero | E4: 45873 | F4: 46240 | G4: numero 202435 (CXX) | H4: 4 pax / 2 DBL | I4: 0 | J4: 0 | K4: =I4/J4 -> #DIV/0! | L4: 2025ITA2546 | M4: excepcionalmente no se cobra 1 noche no show
A5: x | B5: 78954163 | C5: Oystein Himle | D5: Grand Aston La Habana | E5: 45873 | F5: 45877 | G5: RL:26341 | H5: 2 pax / 1 DBL | I5: 114 | J5: 98 | K5: =I5/J5 -> 1.1632653 | L5: PROMO - SUPER EBB 2025 - 002
A6: x | B6: 78954761 | C6: MARIA DELFINA x 2 | D6: Melia Internacional Varadero | E6: 45873 | F6: 45878 | G6: 206384 | H6: 2 pax / 1 DBL | I6: 990 | J6: 945 | K6: =I6/J6 -> 1.047619 | L6: 2025ITA2546 | M6: Markup 5%
A7: x | B7: 78954761 | C7: MARIA DELFINA x 2 | D7: Melia las Americas | E7: 45878 | F7: 45880 | G7: Nro.59311 | H7: 2 pax / 1 DBL | I7: 396 | J7: 332.52 | K7: =I7/J7 -> 1.1909058 | L7: 2025ITA2546 | M7: desvío del Internacional
B8: 78953802 | C8: Virgilio Olivera X3 | D8: Melia Las Dunas | E8: 45874 | F8: 45877 | G8: CXX | H8: 2+1 / 1 DBL | I8: 0 | J8: 0 | K8: =I8/J8 -> #DIV/0! | L8: 2025ITA2546 | M8: Markup 5%
B9: 78953803 | C9: Alisvel Olivera x2 | D9: Melia Las Dunas | E9: 45874 | F9: 45877 | G9: CXX | H9: 4 pax / 2 DBL | I9: 0 | J9: 0 | K9: =I9/J9 -> #DIV/0! | L9: 2025ITA2546 | M9: Markup 5%
A10: x | B10: 78954553 | C10: JUDITH VANESSA TURIN x3 / CRISTAL LADY CHAVEZ 2+1 | D10: Melia Internacional | E10: 5/8/20525 | F10: 45878 | G10: 204640 | H10: 3 pax /1 TRP+ 2+1 / DBL | I10: 1920.6 | J10: 1833.3 | K10: =I10/J10 -> 1.047619 | L10: 2025ITA2546 | M10: Markup 5%
B11: 78954561 | C11: Martha Tellez Roque | D11: Selectum Family Varadero | E11: 45874 | F11: 45877 | G11: RL-23159 | H11: 2 pax / 1 DBL | I11: 0 | J11: 0 | K11: =I11/J11 -> #DIV/0! | L11: SPECIAL PROMOTION TOUCH TOURIZM 2025 | M11: precio Ege
A12: x | B12: 78954678 | C12: Martha Tellez Roque | D12: Selectum Family Varadero | E12: 45874 | F12: 45877 | G12: RL-23358 | H12: 2 pax / 1 DBL | I12: 270 | J12: 252 | K12: =I12/J12 -> 1.0714286 | L12: SPECIAL PROMOTION TOUCH TOURIZM 2025 | M12: Markup 5%
A13: x | B13: 78953837 | C13: FERNANDO GUERRA x2 | D13: Melia Internacional | E13: 45875 | F13: 45883 | G13: 200427 | H13: 2 pax/ 1 DBL | I13: 1296 | J13: 1232 | K13: =I13/J13 -> 1.0519481 | L13: 2025ITA2546 | M13: Markup 5%
B14: 78953863 | C14: PATRICIA BEATRIZ x2 | D14: Paradisus Varadero | E14: 45876 | F14: 45887 | G14: No 358698 (CXX) | H14: 2 pax/ 1 DBL | I14: 0 | J14: 0 | K14: =I14/J14 -> #DIV/0! | L14: 2025ITA2546 | M14: incidencia
A15: x | B15: 78954536 | C15: VIOLETA PEREYRA x2 | D15: Melia Internacional | E15: 45881 | F15: 45885 | G15: 204582 | H15: 2 pax/ 1 DBL | I15: 648 | J15: 616 | K15: =I15/J15 -> 1.0519481 | L15: 2025ITA2546 | M15: Markup 5%
B16: 78953813 | C16: MARIA FERNANDA x2 | D16: Paradisus Varadero | E16: 45883 | F16: 45886 | G16: No 358472. CXX | H16: 2 pax/ 1 DBL | I16: 0 | J16: 0 | K16: =I16/J16 -> #DIV/0! | L16: 2025ITA2546 | M16: incidencia
A17: x | B17: 78954784 | C17: Melissa Sdrowok / Alejandro Averoff | D17: Melia las Americas | E17: 45884 | F17: 45885 | G17: Nro.59851 | H17: 2 pax/ 1 DBL | I17: 142 | J17: 166.26 | K17: =I17/J17 -> 0.85408396 | L17: 2025ITA2546 | M17: reserva original Melia Varadero. clientes aceptaron desvío a Americas / Se les ofreció hotel Paradisus que es mismo precio pero no aceptaron.
A18: x | B18: 78953214 | C18: Giuseppe ALLIEVO x 2 | D18: MYSTIQUE TRINIDAD BY ROYALTON | E18: 45886 | F18: 45888 | G18: RL 6577 | H18: 2 pax / 1 DBL | I18: 168 | J18: 160 | K18: =I18/J18 -> 1.05 | L18: 2025 TUR 003 TOUCH
A19: x | B19: 78954919 | C19: Isabella Bulla Fuentes | D19: Melia Peninsula Varadero | E19: 45886 | F19: 45890 | G19: No .379452 | H19: 1+1 / 1 HAB | I19: 328 | J19: 312 | K19: =I19/J19 -> 1.0512821 | L19: 2025ITA2923
A20: x | B20: 78953395 | C20: ANNA KROFT /VADIM KOZHEMIAKIN / ROMANI RUDOVSKI | D20: GRAND ASTON VARADERO | E20: 45888 | F20: 45889 | G20: RL-26825 | H20: 6 Pax / 3 DBL | I20: 354 | J20: 300 | K20: =I20/J20 -> 1.18 | L20: PROMO - SUPER EBB 2025 - 002
B21: 78953888 | C21: Claudia Yenet Zaldivar x4 | D21: Melia Internacional | E21: 45889 | F21: 45896 | G21: 201210 (CXX) | H21: 2+2 / 1 DBL | I21: 0 | J21: 0 | K21: =I21/J21 -> #DIV/0! | L21: 2025ITA2546 | M21: Markup 5%
B22: 78954099 | C22: GERSON RAMIREZ /EDMUNDO SEMINARIO | D22: Melia Cayo Santa Maria | E22: 45890 | F22: 45893 | G22: CXX | H22: 4 pax / 2 DBL | I22: 0 | J22: 0 | K22: =I22/J22 -> #DIV/0! | L22: 2025ITA2546 | M22: Markup 5%
A23: x | B23: 78955201 | C23: Sissi Lorena Flieger/Michel Aguilar | D23: GRAND ASTON VARADERO | E23: 45891 | F23: 45893 | G23: RL-30824 | H23: 2 pax / 1 DBL | I23: 168 | J23: 160 | K23: =I23/J23 -> 1.05 | L23: PROMO - SUPER EBB 2025 - 002
A24: x | B24: 78955263 | C24: Melak Chebiri x 4 | D24: Melia Trinidad Peninsula | E24: 45894 | F24: 45899 | G24: No. 25308 | H24: 4 pax / 2 DBL | I24: 256 | J24: 0 | K24: =I24/J24 -> #DIV/0! | L24: 2025ITA2546 | M24: NO show, cobrar a Paximum 1 noche de penalidad (64 usd por 4 pax) / Hotel cancela sin penalidad a nosotros
A25: x | B25: 78954631 | C25: LEIDY CASTRO x2 | D25: Melia Peninsula Varadero | E25: 45895 | F25: 45837 | G25: No .379117 | H25: 2 pax / 1 DBL | I25: 246 | J25: 234 | K25: =I25/J25 -> 1.0512821 | L25: 2025ITA2923 | M25: Markup 5%
A26: x | B26: 78955089 | C26: Victor Rolando / Mayda Matilde | D26: GRAND ASTON VARADERO | E26: 45895 | F26: 45897 | G26: RL-30732 | H26: 4 pax / 2 DBL | I26: 336 | J26: 320 | K26: =I26/J26 -> 1.05 | L26: PROMO - SUPER EBB 2025 - 002
A27: x | B27: 78955421 | C27: Yendry Rojas Pereda / Dayma Estrada | D27: GRAND ASTON VARADERO | E27: 45895 | F27: 45897 | G27: RL-31266 | H27: 2 pax / 1 DBL | I27: 168 | J27: 160 | K27: =I27/J27 -> 1.05 | L27: PROMO - SUPER EBB 2025 - 002
A28: x | B28: 78955242 | C28: yanick desnoyers x3 | D28: Melia Internacional | E28: 45895 | F28: 45897 | G28: 208069 | H28: 2+1 /1 DBL | I28: 396 | J28: 378 | K28: =I28/J28 -> 1.047619 | L28: 2025ITA2546 | M28: markup 5%
A29: x | B29: 78954891 | C29: EURIDICE MARLENNE x4 | D29: Melia Cayo Santa Maria | E29: 45897 | F29: 45900 | G29: 164326 | H29: 2+2 / 1 HAB | I29: 378 | J29: 359.1 | K29: =I29/J29 -> 1.0526316 | L29: 2025ITA2546 | M29: markup 5%
A30: x | B30: 78954891 | C30: SANTIAGO ALEJANDRO x 2 | D30: Melia Cayo Santa Maria | E30: 45897 | F30: 45900 | G30: 164326 | H30: 2 pax / 1 DBL | I30: 252 | J30: 239.4 | K30: =I30/J30 -> 1.0526316 | L30: 2025ITA2546 | M30: markup 5%
A31: x | B31: 78955418 | C31: Leonardo Eliasx3 | D31: Melia Habana | E31: 45897 | F31: 45901 | G31: 636347 | H31: 2+1 / 1 DBL | I31: 424 | J31: 403.2 | K31: =I31/J31 -> 1.0515873 | L31: 2025ITA2546 | M31: markup 5%
A32: x | B32: 78953815 | C32: CARMEN AMADOR x3 | D32: Paradisus Varadero | E32: 45898 | F32: 45902 | G32: No 358467. | H32: 3 pax / 1 TRP | I32: 604.2 | J32: 684 | K32: =I32/J32 -> 0.88333333 | L32: 2025ITA2546 | M32: incidencia
A33: x | B33: 78955051 | C33: CARLOS TRUJILLO 2 | D33: Melia Peninsula Varadero | E33: 45898 | F33: 45901 | G33: No .379832 | H33: 2 pax / 1 DBL | I33: 246 | J33: 234 | K33: =I33/J33 -> 1.0512821 | L33: 2025ITA2923 | M33: Markup 5%
B34: 78953814 | C34: Jackie Amador x 3 | D34: Paradisus Varadero | E34: 45899 | F34: 45903 | G34: CXX | H34: 3 pax / 1 TRP | I34: 0 | J34: 0 | K34: =I34/J34 -> #DIV/0! | L34: 2025ITA2546 | M34: Markup 5%
A35: x | B35: 78955158 | C35: YULIA SHESTAKOVA x 2 | D35: Selectum Family Varadero | E35: 45899 | F35: 45900 | G35: RL-24013 | H35: 2 pax / 1 DBL | I35: 90 | J35: 84 | K35: =I35/J35 -> 1.0714286 | L35: SPECIAL PROMOTION TOUCH TOURIZM 2025
I40: =SUM(I3:I39) -> 10574.8 | J40: =SUM(J3:J39) -> 9868.18 | K40: =I40/J40 -> 1.0716059
I42: Revenue | J42: =I40-J40 -> 706.62

Sheet SEPTIEMBRE 2025
B2: PAXIMUM CODE | C2: CLIENTS NAMES | D2: HOTELS | E2: From | F2: to | G2: Hotel confirmation | H2: PAX / ROOM | I2: Sale Price PAXIMUM | J2: TOUCH COST | K2: PROFIT % | L2: VALID RATES TO APPLY | M2: REMARKS
A3: X | B3: 78955589 | C3: Olga Lidia Díaz x 2 | D3: Melia Peninsula Varadero | E3: 45905 | F3: 45907 | G3: No.380537 | H3: 2 pax / 1 DBL | I3: 164 | J3: 156 | K3: =I3/J3 -> 1.0512821 | L3: 2025ITA2923 | M3: Markup 5%
A4: X | B4: 78953872 | C4: Ana Kelland x2 | D4: Paradisus Varadero | E4: 45908 | F4: 45915 | G4: No.358574 | H4: 2 pax / 1 DBL | I4: 742 | J4: 840 | K4: =I4/J4 -> 0.88333333 | L4: 2025ITA2546 | M4: INCIDENCIA
B5: 78953080 | C5: JUAN DANIEL HERNANDEZ PEREZ /Mr FABIAN GALVEZ RAMOS | D5: MYSTIQUE HABANA | E5: 45913 | F5: 45915 | G5: RL8787 | H5: 4 pax / 2 DBL | I5: 0 | J5: 0 | K5: =I5/J5 -> #DIV/0! | L5: 2025 TUR 003
B6: 78955040 | C6: DIEGO ALESSIO | D6: MELIA INTERNACIONAL | E6: 45911 | F6: 45919 | G6: 206929 (CXX) | H6: 2 pax / 1 HAB | I6: 0 | J6: 0 | K6: =I6/J6 -> #DIV/0! | L6: 2025ITA2546 | M6: Markup 5%
B7: 78950731 | C7: NANCY MENDEZ/ MARIO BARBOSA | D7: MEMORIES MIRAMAR | E7: 45915 | F7: 45917 | G7: No:308053 (CXX) | H7: 2 pax / 1 HAB | I7: 0 | J7: 0 | K7: =I7/J7 -> #DIV/0! | L7: 2025 TUR 001 | M7: File de Ege - reserva online del sitio Paximum
A8: X | B8: 78954336 | C8: NANCY MENDEZ / LUZ GUARIN | D8: MEMORIES MIRAMAR | E8: 45915 | F8: 45917 | G8: No:308053. | H8: 2 pax / 1 DBL | I8: 136 | J8: 128 | K8: =I8/J8 -> 1.0625 | L8: 2025 TUR 004 | M8: cambio de loc y nombre , antes 78950731
A9: X | B9: 78955670 | C9: PABLO SEBASTIAN CUELLO x3 | D9: MELIA INTERNACIONAL | E9: 45919 | F9: 45833 | G9: numero 211205 | H9: 2+1 / 1 DBL | I9: 972 | J9: 924 | K9: =I9/J9 -> 1.0519481 | L9: 2025ITA2546 | M9: Markup 5%
B10: 78952752 | C10: Cristian Cruz X 2 | D10: Selectum Family Varadero | E10: 45920 | F10: 45921 | G10: RL-20208 (CXX) | H10: 2 pax / 1 HAB | I10: 0 | J10: 0 | K10: =I10/J10 -> #DIV/0! | L10: B2B Special Promotion
A11: X | B11: 78955487 | C11: ANDREI KNIAZIK / MARIIA KNIAZIK | D11: SOL Varadero Beach | E11: 45920 | F11: 45934 | G11: No.57324 | H11: 2 pax / 1 DBL | I11: 1344 | J11: 1274 | K11: =I11/J11 -> 1.0549451 | L11: 2025ITA2923 | M11: Markup 5%
A12: X | B12: 78954731 | C12: Lisa Utke /Thomas Denzel | D12: MELIA INTERNACIONAL | E12: 45922 | F12: 45898 | G12: 205617 | H12: 2 pax / 1 DBL | I12: 1134 | J12: 1078 | K12: =I12/J12 -> 1.0519481 | L12: 2025ITA2546 | M12: Markup 5%
B13: 78955081 | C13: CLAUDIA ARBAIZA | D13: MELIA INTERNACIONAL | E13: 45926 | F13: 45929 | G13: 207292 (CXX) | H13: 3 PAX / 1 TRP | I13: 0 | J13: 0 | K13: =I13/J13 -> #DIV/0! | L13: 2025ITA2546 | M13: Markup 5%
B14: 78955788 | C14: Michel Angel Castillo x 2 | D14: Selectum Family Varadero | E14: 45926 | F14: 45930 | G14: RL-25067 (CXX) | H14: 2 pax/ 1 Dbl | I14: 0 | J14: 0 | K14: =I14/J14 -> #DIV/0! | L14: B2B Special Promotion
A15: X | B15: 78953792 | C15: VICTOR RICARDO X2 / ESTEBAN ALEJANDRO X2 | D15: MELIA INTERNACIONAL | E15: 45927 | F15: 45932 | G15: 200352 | H15: 4 pax / 2 DBL | I15: 1620 | J15: 1540 | K15: =I15/J15 -> 1.0519481 | L15: 2025ITA2546 | M15: Markup 5%
A16: X | B16: 81545466 | C16: Angel Casanova | D16: Melia Peninsula Varadero | E16: 45927 | F16: 45930 | G16: No.380793 | H16: 1 pax/ 1 SGL | I16: 168 | J16: 162 | K16: =I16/J16 -> 1.037037 | L16: 2025ITA3189
A17: X | B17: 81545692 | C17: POLINA MASLOVA | D17: GRAND ASTON VARADERO | E17: 45927 | F17: 45931 | G17: RL-32961 | H17: 1 pax/ 1 SGL ov | I17: 252 | J17: 240 | K17: =I17/J17 -> 1.05 | L17: PROMO - SUPER EBB 2025 - 002 | M17: Sergio y hotel confirmaron 60 usd pppn en sencilla ocean view
A18: X | B18: 81545691 | C18: Miika Ojatalo X 2 | D18: MELIA HABANA | E18: 45927 | F18: 45932 | G18: nro 637398 | H18: 2 PAX / 1 dbl | I18: 530 | J18: 504 | K18: =I18/J18 -> 1.0515873 | L18: 2025ITA2546
A19: X | C19: Jimi B Saarenpaa X 2 | D19: MELIA HABANA | E19: 45927 | F19: 45932 | G19: nro 637398 | H19: 2 PAX / 1 dbl | I19: 530 | J19: 504 | K19: =I19/J19 -> 1.0515873 | L19: 2025ITA2546
A20: X | B20: 81545700 | C20: MAKSIM VAZHNIK | D20: MELIA HABANA | E20: 45927 | F20: 45941 | G20: nro 637397 | H20: 1 pax / 1 SGL | I20: 1162 | J20: 1125.6 | K20: =I20/J20 -> 1.0323383 | L20: 2025ITA2546
I25: =SUM(I3:I24) -> 8754 | J25: =SUM(J3:J24) -> 8475.6 | K25: =I25/J25 -> 1.0328472
I27: Revenue | J27: =I25-J25 -> 278.4

Sheet OCTUBRE 2025
B2: PAXIMUM CODE | C2: CLIENTS NAMES | D2: HOTELS | E2: From | F2: to | G2: Hotel confirmation | H2: PAX / ROOM | I2: Sale Price PAXIMUM | J2: TOUCH COST | K2: PROFIT % | L2: VALID RATES TO APPLY | M2: NATIONALITY | N2: REMARKS
A3: x | B3: 81545472 | C3: Yanela Hernandez X 2 | D3: Melia las Antillas | E3: 45935 | F3: 45937 | G3: # 236912 | H3: 2 PAX / 1 DBL | I3: 176 | J3: 168 | K3: =I3/J3 -> 1.047619 | L3: 2025ITA2546
A4: x | B4: 78955390 | C4: Angela marcela linares | D4: Sol Varadero Beach | E4: 45936 | F4: 45940 | G4: No. 57025 | H4: 1 pax / 1 SGL | I4: 192 | J4: 182 | K4: =I4/J4 -> 1.0549451 | L4: 2015ITA2923 | N4: Markup 5%
A5: x | B5: 78955778 | C5: Ledismaida / Luis Enrique / Daniel Alejandro / Rachel | D5: Melia Trinidad Peninsula | E5: 45936 | F5: 45937 | G5: No. 26495 | H5: 12 pax / 4TRP | I5: 729.6 | J5: 694.24 | K5: =I5/J5 -> 1.0509334 | L5: 2025ITA2546 | N5: Markup 5%
B6: 81545585 | C6: Lazaro Luis Gonzalez x 2 | D6: Melia Peninsula Varadero | E6: 45938 | F6: 45940 | G6: No. 380986 (CXX) | H6: 2 PAX / 1 DBL | I6: 0 | J6: 0 | K6: =I6/J6 -> #DIV/0! | L6: 2025ITA3189
A7: x | B7: 81545943 | C7: ALEKSANDR THOMSON x 2 | D7: Melia Las Américas | E7: 45938 | F7: 45943 | G7: Nro.63643 | H7: 2 PAX / 1 DBL | I7: 930 | J7: 735 | K7: =I7/J7 -> 1.2653061 | L7: 2025ITA2546
A8: x | B8: 81545852 | C8: Huu Doanh Le | D8: Melia Varadero | E8: 45939 | F8: 45940 | G8: No .645964 | H8: 1 pax / 1 SGL SV | I8: 106 | J8: 91 | K8: =I8/J8 -> 1.1648352 | L8: 2025ITA3189
A9: x | B9: 81545852 | C9: Thi Dao Huynh X 2 | D9: Melia Varadero | E9: 45939 | F9: 45940 | G9: No .645964 | H9: 2 PAX / 1 DBL SV | I9: 142 | J9: 136.5 | K9: =I9/J9 -> 1.040293 | L9: 2025ITA3189
A10: x | B10: 81545852 | C10: Quang Minh Nguyen X 2 | D10: Melia Varadero | E10: 45939 | F10: 45940 | G10: No .645964 | H10: 2 PAX / 1 DBL SV | I10: 142 | J10: 136.5 | K10: =I10/J10 -> 1.040293 | L10: 2025ITA3189
A11: x | B11: 81545861 | C11: Victor Martinez x 2 | D11: Nacional de Cuba | E11: 45939 | F11: 45942 | G11: No/ 481751 | H11: 2 PAX / 1 DBL sv | I11: 360 | J11: 324 | K11: =I11/J11 -> 1.1111111 | L11: EXT DVA VER 25
A12: x | B12: 81545861 | C12: Jose Luis B Castillo x 2 | D12: Nacional de Cuba | E12: 45939 | F12: 45942 | G12: No/ 481751 | H12: 2 PAX / 1 DBL | I12: 318 | J12: 288 | K12: =I12/J12 -> 1.1041667 | L12: EXT DVA VER 25
B13: 78954097 | C13: Cristian Aguirre x2 | D13: Melia Cohiba | E13: 45940 | F13: 45941 | G13: No.710795.(CXX) | H13: 2 PAX / 1 DBL | I13: 0 | J13: 0 | K13: =I13/J13 -> #DIV/0! | L13: 2025ITA2546 | N13: Markup 5%
B14: 78954098 | C14: Enrique Aubrich X 2 | D14: Melia Cohiba | E14: 45940 | F14: 45941 | G14: No.710338. (CXX) | H14: 2 PAX / 1 DBL | I14: 0 | J14: 0 | K14: =I14/J14 -> #DIV/0! | L14: 2025ITA2546 | N14: Markup 5%
B15: 81545653 | C15: JOAQUIN JOSE CHACON GUADALIX x2 | D15: Nacional de Cuba | E15: 45940 | F15: 45949 | G15: No. 481513 (CXX) | H15: 2 PAX / 1 DBL | I15: 0 | J15: 0 | K15: =I15/J15 -> #DIV/0! | L15: SPO-HNC26-TOUCH | N15: Paximum vendió por error suyo MAP a precio e CP, se reservó CP y se informó no podemos asumir la cena o pedir que el hotel lo haga
A16: x | B16: 81545686 | C16: Lorenzo Conte x 2 | D16: Melia Varadero | E16: 45940 | F16: 45949 | G16: No .645451 | H16: 2 PAX / 1 DBL | I16: 990 | J16: 936 | K16: =I16/J16 -> 1.0576923 | L16: 2025ITA3189
A17: x | B17: 81545686 | C17: Christian B Eichwald x 2 | D17: Melia Varadero | E17: 45940 | F17: 45949 | G17: No .645451 | H17: 2 PAX / 1 DBL | I17: 990 | J17: 936 | K17: =I17/J17 -> 1.0576923 | L17: 2025ITA3189
A18: x | B18: 81545805 | C18: Gilma O Farrill x2 | D18: Selectum Family Varadero | E18: 45940 | F18: 45943 | G18: RL-25745 | H18: 2 PAX / 1 DBL | I18: 270 | J18: 252 | K18: =I18/J18 -> 1.0714286 | L18: B2B Special Promotion
A19: x | B19: 81545916 | C19: Farah Maria Leal Machado x 2 | D19: Sol Caribe Beach | E19: 45940 | F19: 45943 | G19: No. 34913 | H19: 2 PAX / 1 DBL | I19: 288 | J19: 273 | K19: =I19/J19 -> 1.0549451 | L19: 2015ITA2923
A20: x | B20: 81545917 | C20: Maria Fernanda Torres x 2 | D20: Sol Caribe Beach | E20: 45940 | F20: 45943 | G20: No. 34914 | H20: 2 PAX / 1 DBL | I20: 288 | J20: 273 | K20: =I20/J20 -> 1.0549451 | L20: 2015ITA2923
A21: x | B21: 81545795 | C21: Gerald Garceau x 2 | D21: Sol Caribe Beach | E21: 45942 | F21: 45949 | G21: 34661 | H21: 2 PAX / 1 DBL | I21: 672 | J21: 637 | K21: =I21/J21 -> 1.0549451 | L21: 2015ITA2923 | N21: Reserva original Sol Varadero Beach
A22: x | B22: 81545850 | C22: ALVARO ALVARADO | D22: Melia Peninsula Varadero | E22: 45942 | F22: 45945 | G22: No. 381251 | H22: 1 pax / 1 SGL | I22: 168 | J22: 162 | K22: =I22/J22 -> 1.037037 | L22: 2025ITA3189
A23: x | B23: 81545796 | C23: Gaetane Garceau x1 | D23: Sol Caribe Beach | E23: 45942 | F23: 45949 | G23: 34662 | H23: 1 pax / 1 SGL | I23: 336 | J23: 318.5 | K23: =I23/J23 -> 1.0549451 | L23: 2015ITA2923 | N23: Reserva original Sol Varadero Beach
A24: x | B24: 78955422 | C24: Mrs Maren Witt | D24: Sol Varadero Beach | E24: 45943 | F24: 45947 | G24: No.57161 | H24: 1 pax / 1 SGL | I24: 192 | J24: 182 | K24: =I24/J24 -> 1.0549451 | L24: 2015ITA2923 | N24: Markup 5%
A25: x | B25: 81545678 | C25: Peter Kohler | D25: Sol Varadero Beach | E25: 45943 | F25: 45947 | G25: No.58770 | H25: 1 pax / 1 SGL | I25: 192 | J25: 182 | K25: =I25/J25 -> 1.0549451 | L25: 2015ITA2923 | N25: Markup 5%
A26: x | B26: 81545708 | C26: IVAN SAENKO x 2 | D26: Melia Habana | E26: 45943 | F26: 45944 | G26: nro 637399 | H26: 2 PAX / 1 DBL | I26: 106 | J26: 100.8 | K26: =I26/J26 -> 1.0515873 | L26: 2025ITA2546
A27: x | B27: 81545506 | C27: SERGIO ARELLANO x 4 | D27: Melia Internacional | E27: 45944 | F27: 45947 | G27: numero 213180 | H27: 2+2 / 1 DBL | I27: 607.5 | J27: 577.5 | K27: =I27/J27 -> 1.0519481 | L27: 2025ITA2546 | N27: Markup 5%
A28: x | B28: 81545799 | C28: Pierre Proulx x 1 | D28: Sol Caribe Beach | E28: 45945 | F28: 45949 | G28: 34663 | H28: 1 pax / 1 SGL | I28: 192 | J28: 182 | K28: =I28/J28 -> 1.0549451 | L28: 2015ITA2923 | N28: Reserva original Sol Varadero Beach
A29: x | B29: 81545849 | C29: Dariel Gonzalez Navarro x 2 | D29: Selectum Family Varadero | E29: 45945 | F29: 45947 | G29: RL-25825 | H29: 2 PAX / 1 DBL | I29: 180 | J29: 168 | K29: =I29/J29 -> 1.0714286 | L29: B2B Special Promotion
A30: x | B30: 81545975 | C30: JOSE LUIS SALMERON x 2 | D30: Melia Trinidad Peninsula | E30: 45945 | F30: 38642 | G30: No. 27897 . | H30: 2 PAX / 1 DBL | I30: 280 | J30: 266.8 | K30: =I30/J30 -> 1.0494753 | L30: 2025ITA2546
A31: x | B31: 81545975 | C31: ISMAIL MOHAMED x 2 | D31: Melia Trinidad Peninsula | E31: 45945 | F31: 38642 | G31: No. 27897 . | H31: 2 PAX / 1 DBL | I31: 280 | J31: 266.8 | K31: =I31/J31 -> 1.0494753 | L31: 2025ITA2546
B32: 78953947 | C32: ERJONA DERVISHI / GRISELDA OSMANI | D32: Melia Internacional | E32: 45945 | F32: 45948 | G32: 201628 CXX | H32: 5 / 1 TRP+1 DBL | I32: 0 | J32: 0 | K32: =I32/J32 -> #DIV/0! | L32: 2025ITA2546 | N32: Markup 5%
A33: x | B33: 81545899 | C33: Sabine Suchland x2 | D33: Melia Habana | E33: 45946 | F33: 45949 | G33: nro 637778 | H33: 2 PAX / 1 DBL | I33: 318 | J33: 302.4 | K33: =I33/J33 -> 1.0515873 | L33: 2025ITA2546
A34: x | B34: 81545899 | C34: Olaf Koschnitzke x2 | D34: Melia Habana | E34: 45946 | F34: 45949 | G34: nro 637778 | H34: 2 PAX / 1 DBL | I34: 318 | J34: 302.4 | K34: =I34/J34 -> 1.0515873 | L34: 2025ITA2546
A35: x | B35: 81546074 | C35: ADRIANA ELSA DIAZ x 3 | D35: Tryp Habana Libre | E35: 45946 | F35: 45948 | G35: No R-251016-664170 | H35: 3 pax / 1 TRP pv | I35: 296.4 | J35: 251.37 | K35: =I35/J35 -> 1.1791383 | L35: 2025ITA2546 | N35: error en precio x Paximum se le comunicó , confirmaron ajuste de precio al correcto
B36: 78954022 | C36: Alvaro Briz x 2 | D36: Melia Peninsula Varadero | E36: 45948 | F36: 45949 | G36: No .379463 CXX | H36: 2 PAX/ 1 HAB | I36: 0 | J36: 0 | K36: =I36/J36 -> #DIV/0! | L36: 2015ITA2923 | N36: Markup 5% / reserva por otra agencia
B37: 78954237 | C37: CLAUDIA CARAJULCA | D37: Melia Cayo Santa María | E37: 45949 | F37: 45952 | G37: CXX | H37: 2 pax / 1 DBL | I37: 0 | J37: 0 | K37: =I37/J37 -> #DIV/0! | L37: 2025ITA2546 | N37: Markup 5%
A38: x | B38: 78953882 | C38: Daria Shipilova /Tatiana Shipilova | D38: Paradisus Varadero | E38: 45951 | F38: 45960 | G38: No.358582 | H38: 5+1/1TRP+1 DBL | I38: 2313.45 | J38: 2619 | K38: =I38/J38 -> 0.88333333 | L38: 2025ITA2546 | N38: incidencia
A39: x | B39: 81545474 | C39: Susana Infiesta X 2 | D39: Melia Varadero | E39: 45951 | F39: 45961 | G39: No .645014 | H39: 2 PAX / 1 DBL | I39: 1100 | J39: 1040 | K39: =I39/J39 -> 1.0576923 | L39: 2025ITA3189
A40: x | B40: 81545776 | C40: MITCHELL GAVIN TONY KENNY x 2 | D40: Melia Internacional | E40: 45951 | F40: 45957 | G40: numero 214865 | H40: 2 PAX / 1 DBL | I40: 972 | J40: 924 | K40: =I40/J40 -> 1.0519481 | L40: 2025ITA2546
A41: x | B41: 81546084 | C41: INES RODRIGUEZ BENITO x 2 | D41: Melia Peninsula Varadero | E41: 45952 | F41: 45956 | G41: No. 381557 | H41: 2 PAX / 1 DBL | I41: 320 | J41: 304 | K41: =I41/J41 -> 1.0526316 | L41: 2025ITA3189
...

Sheet NOVIEMBRE 2025
B2: PAXIMUM CODE | C2: CLIENTS NAMES | D2: HOTELS | E2: From | F2: to | G2: Hotel confirmation | H2: PAX / ROOM | I2: Sale Price PAXIMUM | J2: TOUCH COST | K2: PROFIT % | L2: VALID RATES TO APPLY | M2: NATIONALITY | N2: REMARKS
K3: =I3/J3 -> #DIV/0!
K4: =I4/J4 -> #DIV/0!
K5: =I5/J5 -> #DIV/0!
K6: =I6/J6 -> #DIV/0!
K7: =I7/J7 -> #DIV/0!
K8: =I8/J8 -> #DIV/0!
K9: =I9/J9 -> #DIV/0!
K10: =I10/J10 -> #DIV/0!
K11: =I11/J11 -> #DIV/0!
K12: =I12/J12 -> #DIV/0!
K13: =I13/J13 -> #DIV/0!
K14: =I14/J14 -> #DIV/0!
I15: =SUM(I3:I14) -> 0 | J15: =SUM(J3:J14) -> 0 | K15: =I15/J15 -> #DIV/0!
I17: Revenue | J17: =I15-J15 -> 0

Sheet DICIEMBRE 2025
B2: PAXIMUM CODE | C2: CLIENTS NAMES | D2: HOTELS | E2: From | F2: to | G2: Hotel confirmation | H2: PAX / ROOM | I2: Sale Price PAXIMUM | J2: TOUCH COST | K2: PROFIT % | L2: VALID RATES TO APPLY | M2: NATIONALITY | N2: REMARKS
B3: 81545816 | C3: Adrian Henriquez | D3: Grand Aston La Habana | E3: 46005 | F3: 46008 | G3: RL:28772 (CXX) | H3: 2 PAX / 1 DBL | I3: 0 | J3: 0 | K3: =I3/J3 -> #DIV/0! | L3: RUBI2526
K4: =I4/J4 -> #DIV/0!
K5: =I5/J5 -> #DIV/0!
K6: =I6/J6 -> #DIV/0!
K7: =I7/J7 -> #DIV/0!
K8: =I8/J8 -> #DIV/0!
K9: =I9/J9 -> #DIV/0!
K10: =I10/J10 -> #DIV/0!
K11: =I11/J11 -> #DIV/0!
I17: =SUM(I3:I16) -> 0 | J17: =SUM(J3:J16) -> 0 | K17: =I17/J17 -> #DIV/0!
I19: Revenue | J19: =I17-J17 -> 0

Sheet Consolidado
A1: CONSOLIDADO 2025 | G1: CONSOLIDADO 2025
A2: MESES | B2: VENTA PAXIMUM | C2: COSTO HOTEL | D2: PROFIT % | E2: PROFIT VALOR | G2: VENTA PAXIMUM | H2: COSTO HOTEL | I2: PROFIT % | J2: PROFIT VALOR | L2: VENTA PAXIMUM | M2: COSTO HOTEL | N2: PROFIT % | O2: PROFIT VALOR
A3: ENERO | B3: ='Enero 2025'!G5 -> 672 | C3: ='Enero 2025'!H5 -> 540 | D3: =B3/C3 -> 1.2444444 | E3: =B3-C3 -> 132 | G3: 672 | H3: 540 | I3: 1.2444 | J3: 132 | L3: 672 | M3: 540 | N3: 1.2444 | O3: 132
A4: FEBRERO | B4: ='Febrero 2025'!H14 -> 1926 | C4: ='Febrero 2025'!I14 -> 1632 | D4: =B4/C4 -> 1.1801471 | E4: =B4-C4 -> 294 | G4: 1926 | H4: 1632 | I4: 1.1801 | J4: 294 | L4: 1926 | M4: 1632 | N4: 1.1801 | O4: 294
A5: MARZO | B5: ='MARZO 2025'!G16 -> 2126 | C5: ='MARZO 2025'!H16 -> 1976 | D5: =B5/C5 -> 1.0759109 | E5: =B5-C5 -> 150 | G5: 2126 | H5: 1976 | I5: 1.0759 | J5: 150 | L5: 2126 | M5: 1976 | N5: 1.0759 | O5: 150
A6: ABRIL | B6: ='ABRIL 2025'!I19 -> 2310 | C6: ='ABRIL 2025'!J19 -> 2038 | D6: =B6/C6 -> 1.1334642 | E6: =B6-C6 -> 272 | G6: 2310 | H6: 2038 | I6: 1.1335 | J6: 272 | L6: 2310 | M6: 2038 | N6: 1.1335 | O6: 272
A7: MAYO | B7: ='MAYO 2025'!I12 -> 1256 | C7: ='MAYO 2025'!J12 -> 1026 | D7: =B7/C7 -> 1.2241715 | E7: =B7-C7 -> 230 | G7: 1256 | H7: 1026 | I7: 1.2242 | J7: 230 | L7: 1256 | M7: 1026 | N7: 1.2242 | O7: 230
A8: JUNIO | B8: ='JUNIO 2025'!I22 -> 2472 | C8: ='JUNIO 2025'!J22 -> 2247.48 | D8: =B8/C8 -> 1.0998986 | E8: =B8-C8 -> 224.52 | G8: 2472 | H8: 2247.48 | I8: 1.0999 | J8: 224.52 | L8: 2472 | M8: 2247.48 | N8: 1.0999 | O8: 224.52
A9: JULIO | B9: ='JULIO 2025'!I40 -> 9315.7 | C9: ='JULIO 2025'!J40 -> 8607.4 | D9: =B9/C9 -> 1.0822897 | E9: =B9-C9 -> 708.3 | G9: 9315.7 | H9: 8654.96 | I9: 1.0763 | J9: 660.74 | L9: 9315.7 | M9: 8607.4 | N9: 1.0823 | O9: 708.3
A10: AGOSTO | B10: ='AGOSTO 2025'!I40 -> 10574.8 | C10: ='AGOSTO 2025'!J40 -> 9868.18 | D10: =B10/C10 -> 1.0716059 | E10: =B10-C10 -> 706.62 | G10: 5794.8 | H10: 5629.3 | I10: 1.0294 | J10: 165.5 | L10: 10574.8 | M10: 9868.18 | N10: 1.0716 | O10: 706.62
A11: SEPTIEMBRE | B11: ='SEPTIEMBRE 2025'!I25 -> 8754 | C11: ='SEPTIEMBRE 2025'!J25 -> 8475.6 | D11: =B11/C11 -> 1.0328472 | E11: =B11-C11 -> 278.4 | G11: 2894 | H11: 2508 | I11: 1.1539 | J11: 386 | L11: 8754 | M11: 8475.6 | N11: 1.0328 | O11: 278.4
A12: OCTUBRE | B12: ='OCTUBRE 2025'!I53 -> 15858.95 | C12: ='OCTUBRE 2025'!J53 -> 15229.81 | D12: =B12/C12 -> 1.0413098 | E12: =B12-C12 -> 629.14 | G12: 8602.1 | H12: 8597.55 | I12: 1.0005 | J12: 4.55 | L12: 16014.55 | M12: 15423.64 | N12: 1.0383 | O12: 590.91
A13: NOVIEMBRE | B13: ='NOVIEMBRE 2025'!I15 -> 0 | C13: ='NOVIEMBRE 2025'!J15 -> 0 | D13: =B13/C13 -> #DIV/0! | E13: =B13-C13 -> 0 | I13: #DIV/0! | J13: 0 | L13: 2956 | M13: 2620 | N13: 1.1282 | O13: 336
A14: DICIEMBRE | B14: ='DICIEMBRE 2025'!I17 -> 0 | C14: ='DICIEMBRE 2025'!J17 -> 0 | D14: =B14/C14 -> #DIV/0! | E14: =B14-C14 -> 0 | I14: #DIV/0! | J14: 0 | L14: 1688.8 | M14: 1477.2 | N14: 1.1432 | O14: 211.6
A15: TOTAL USD | B15: =SUM(B3:B14) -> 55265.45 | C15: =SUM(C3:C14) -> 51640.47 | D15: =B15/C15 -> 1.0701965 | E15: =SUM(E3:E14) -> 3624.98 | G15: 37368.6 | H15: 34849.29 | I15: 1.0723 | J15: 2519.31 | L15: 60065.85 | M15: 55931.5 | N15: 1.0739 | O15: 4134.35
A17: Updated | G17: Updated | H17: 45861 | I17: fecha enviado a Olguita | L17: 45936 | M17: fecha enviado a Olguita

Sheet Cancelaciones 
B2: CODIGO PAXIMUM | C2: NOMBRE DEL CLIENTE | D2: HOTELES | E2: DESDE | F2: HASTA
A3: 1 | B3: 78950916 | C3: Paximun | D3: Memories miramar | E3: 21.01.2023 | F3: 23.01.2025
A4: =A3+1 -> 2 | B4: 78951180 | C4: Paximun | D4: MEMORIES MIRAMAR | E4: 16.02.2025 | F4: 17.02.2025
A5: =A4+1 -> 3 | B5: 78951454 | C5: Paximun | D5: Ib. Parque Central | E5: 27.02.2025 | F5: 02.03.2025
A6: =A5+1 -> 4 | B6: 78951485 | C6: Paximun | D6: Ib. Parque Central | E6: 27.02.2025 | F6: 02.03.2025
A7: =A6+1 -> 5 | B7: 78951109 | C7: Paximun | D7: Aston Habana | E7: 09.02.2025 | F7: 16.02.2025
A8: =A7+1 -> 6 | B8: 78951488 | C8: Paximun | D8: Grand Aston Habana | E8: 02.03.2025 | F8: 03.03.2025
A9: =A8+1 -> 7 | B9: 78951489 | C9: Paximun | D9: Grand Aston Habana | E9: 02.03.2025 | F9: 03.03.2025
A10: =A9+1 -> 8 | B10: 78951490 | C10: Paximun | D10: Grand Aston Habana | E10: 02.03.2025 | F10: 03.03.2025
A11: =A10+1 -> 9 | B11: 78951715 | C11: Paximun | D11: Grand Aston Varadero | E11: 29.03.2025 | F11: 30.03.2025
A12: =A11+1 -> 10 | B12: 78952055 | C12: Paximun | D12: Gran Memories Varadero | E12: 45751 | F12: 45755
A13: =A12+1 -> 11 | B13: 78951086 | C13: Paximun | D13: Grand Aston Varadero | E13: 45752 | F13: 45753
A14: =A13+1 -> 12 | B14: 78951839 | C14: Paximun | D14: Mystique Trinidad La Popa | E14: 45761 | F14: 45766
A15: =A14+1 -> 13 | B15: 78951756 | C15: Paximun | D15: Memories Miramar | E15: 45770 | F15: 45771
A16: =A15+1 -> 14 | B16: 78951761 | C16: Paximun | D16: Memories Miramar | E16: 45770 | F16: 45771
A17: =A16+1 -> 15 | B17: 78952301 | C17: Paximum | D17: Mystique Trinidad La Popa | E17: 45780 | F17: 45781
A18: =A17+1 -> 16 | B18: 78951634 | C18: Paximun | D18: Selectum Varadero | E18: 45824 | F18: 45825
A19: =A18+1 -> 17 | B19: 78953847 | C19: Olivia Ezaru | D19: Paradisus Varadero | E19: 45842 | F19: 45848
A20: =A19+1 -> 18 | B20: 78953762 | C20: TOMAS ISAAC NOWICKI /LUDMILA AYELEN | D20: MELIA INTERNATIONAL | E20: 45846 | F20: 45853
A21: =A20+1 -> 19 | B21: 78953757 | C21: NATASHA REBECA NOWICKI/MARTIN GABRIEL CASCABELO | D21: MELIA INTERNATIONAL | E21: 45846 | F21: 45853
A22: =A21+1 -> 20 | B22: 78953768 | C22: vALENTINA pistarini /franco nahuel | D22: MELIA VARADERO | E22: 45850 | F22: 45857
A23: =A22+1 -> 21 | B23: 78953860 | C23: RICARDO ANTONIO /ARIEL GOMEZ PALACIOS / SERGIO ALEJANDRO | D23: MELIA LAS DUNAS | E23: 45854 | F23: 45862
... A51: =A50+1 -> 49 | B51: 78954287 | C51: CLAUDIA CARAJULCA | D51: Melia Cayo Santa María | E51: 45956 | F51: 45959
B54: meses | C54: total de reservas | D54: confirmadas | E54: canceladas
B55: enero | C55: 2 | D55: 1 | E55: 1 | F55: =D55+E55 -> 2
B56: febrero | C56: 11 | D56: 7 | E56: 4 | F56: =D56+E56 -> 11
B57: marzo | C57: 13 | D57: 9 | E57: 4 | F57: =D57+E57 -> 13
B58: abril | C58: 15 | D58: 10 | E58: 5 | F58: =D58+E58 -> 15
B59: mayo | C59: 7 | D59: 6 | E59: 1 | F59: =D59+E59 -> 7
B60: junio | C60: 12 | D60: 11 | E60: 1 | F60: =D60+E60 -> 12
B61: julio | C61: 29 | D61: 18 | E61: 11 | F61: =D61+E61 -> 29
B62: agosto | C62: 31 | D62: 22 | E62: 9 | F62: =D62+E62 -> 31
B63: septiembre | C63: 9 | D63: 6 | E63: 3 | F63: =D63+E63 -> 9
B64: octubre | C64: 13 | D64: 3 | E64: 10 | F64: =D64+E64 -> 13
B65: noviembre
B66: diciembre
C67: =SUM(C55:C66) -> 142 | D67: =SUM(D55:D66) -> 93 | E67: =SUM(E55:E66) -> 49 | F67: =D67+E67 -> 142
E68: =E67/C67 -> 0.34507042
